<mujoco model="cart">
  <compiler inertiafromgeom="true"/>
  <custom>
    <numeric data="2" name="frame_skip"/>
  </custom>
  <default>
    <joint armature="0" damping="1" limited="true"/>
    <geom contype="0" friction="1 0.1 0.1" rgba="0.7 0.7 0 1"/>
    <tendon/>
    <motor ctrlrange="-3 3"/>
  </default>
  <option gravity="0 0 -9.81" integrator="RK4" timestep="0.02"/>
  <size nstack="3000"/>
  <worldbody>
    <geom name="rail" pos="0 0 0" quat="0.707 0 0.707 0" rgba="0.3 0.3 0.7 1" size="0.02 2" type="capsule"/>

    <body name="cart" pos="0 0 0">
      <joint axis="1 0 0" limited="true" name="slider" pos="0 0 0" range="-1.5 1.5" type="slide"/>
      <geom name="cart" pos="0 0 0" quat="0.707 0 0.707 0" size="0.1 0.1" type="capsule"/>
    </body>

    <body name="target" pos="0. 0. 0.">
      <joint armature="0" axis="1 0 0" damping="0" limited="true" name="target_x" pos="0 0 0" range="-1 1" ref="0" stiffness="0" type="slide"/>
      <geom conaffinity="0" contype="0" name="target" pos="0 0 0" rgba="0.9 0.2 0.2 1" size=".04" type="sphere"/>
    </body>
  </worldbody>
  <actuator>
    <motor gear="100" joint="slider" name="slide"/>
  </actuator>
</mujoco>
